<?xml version="1.0"?>

<robot xmlns:xacro="http://www.ros.org/wiki/xacro" name="ttrobot">

  <xacro:include filename="$(find ttrobot_description)/urdf/rover_gazebo.xacro"/>
  <xacro:include filename="$(find ttrobot_description)/urdf/rover_ros2_control.xacro"/>

  <gazebo>
    <plugin name="gazebo_ros_state" filename="libgazebo_ros_state.so">
      <robotNamespace>/</robotNamespace>
    </plugin>
  </gazebo>

  <link name="base_footprint"/>
    
    <link
    name="base_link">
    <inertial>
      <origin
        xyz="-0.00037006 -0.0041829 -0.05633"
        rpy="0 0 0" />
      <mass
        value="12.25" />
      <inertia
        ixx="0.10386"
        ixy="6.8068E-07"
        ixz="8.4143E-07"
        iyy="0.1719"
        iyz="3.6664E-11"
        izz="0.23796" />
    </inertial>
    <visual>
      <origin
        xyz="0 0 0"
        rpy="0 0 0" />
      <geometry>
        <mesh
          filename="package://ttrobot_description/meshes/base_link.STL" />
      </geometry>
      <material
        name="">
        <color
          rgba="0.79216 0.81961 0.93333 1" />
      </material>
    </visual>
    <collision>
      <origin
        xyz="0 0 0"
        rpy="0 0 0" />
      <geometry>
        <!-- <mesh
          filename="package://ttrobot_description/meshes/base_link.STL" /> -->
          <box size="0.75 0.7 0.3"/>
      </geometry>
    </collision>
  </link>
  <joint name="base_joint" type="fixed">
    <parent link="base_footprint"/>
    <child link="base_link"/>
    <origin rpy="0 0 0" xyz="0 0 1"/>
</joint>
  <link
    name="DirFronIzq_Link">
    <inertial>
      <origin
        xyz="-9.8841E-08 -0.021434 -0.089154"
        rpy="0 0 0" />
      <mass
        value="0.55669" />
      <inertia
        ixx="0.0010591"
        ixy="7.7859E-11"
        ixz="5.9094E-12"
        iyy="0.00067987"
        iyz="6.9652E-05"
        izz="0.00053192" />
    </inertial>
    <visual>
      <origin
        xyz="0 0 0"
        rpy="0 0 0" />
      <geometry>
        <mesh
          filename="package://ttrobot_description/meshes/DirFronIzq_Link.STL" />
      </geometry>
      <material
        name="">
        <color
          rgba="0.79216 0.81961 0.93333 1" />
      </material>
    </visual>
    <collision>
      <origin
        xyz="0 0 0"
        rpy="0 0 0" />
      <geometry>
        <mesh
          filename="package://ttrobot_description/meshes/DirFronIzq_Link.STL" />
      </geometry>
    </collision>
  </link>
  <joint
    name="DirFronIzq_Joint"
    type="continuous">
    <origin
      xyz="0.42145 0.50303 -0.22737"
      rpy="0 0 0" />
    <parent
      link="base_link" />
    <child
      link="DirFronIzq_Link" />
    <axis
      xyz="0 0 1" />
  </joint>
  <link
    name="Rueda1_Link">
    <inertial>
      <origin
        xyz="0.0029957 0.011485 -6.0485E-05"
        rpy="0 0 0" />
      <!-- <mass
        value="0.82973" /> -->
        <mass
        value="3.6" />
      <inertia
        ixx="0.0039112"
        ixy="5.5387E-11"
        ixz="1.8367E-10"
        iyy="0.0062022"
        iyz="-2.8482E-11"
        izz="0.0039112" />
    </inertial>
    <visual>
      <origin
        xyz="0 0 0"
        rpy="0 0 0" />
      <geometry>
        <mesh
          filename="package://ttrobot_description/meshes/Rueda1_Link.STL" />
      </geometry>
      <material
        name="">
        <color
          rgba="0.79216 0.81961 0.93333 1" />
      </material>
    </visual>
    <collision>
      <origin
        xyz="0 0 0"
        rpy="0 0 0" />
      <geometry>
        <mesh
          filename="package://ttrobot_description/meshes/Rueda1_Link.STL" />
          <!-- <cylinder length="0.135" radius="0.1"/> -->
      </geometry>
    </collision>
  </link>
  <joint
    name="Rueda1_Joint"
    type="continuous">
    <origin
      xyz="-0.002996 -0.00014393 -0.13546"
      rpy="0 0 0" />
    <parent
      link="DirFronIzq_Link" />
    <child
      link="Rueda1_Link" />
    <axis
      xyz="0 1 0" />
  </joint>
  <link
    name="Rueda3_Link">
    <inertial>
      <origin
        xyz="-1.9031E-11 0.0067512 -7.2069E-09"
        rpy="0 0 0" />
      <!-- <mass
        value="0.82974" /> -->
        <mass
        value="3.6" />
      <inertia
        ixx="0.0039112"
        ixy="6.2277E-11"
        ixz="-6.0769E-12"
        iyy="0.0062022"
        iyz="1.5091E-12"
        izz="0.0039112" />
    </inertial>
    <visual>
      <origin
        xyz="0 0 0"
        rpy="0 0 0" />
      <geometry>
        <mesh
          filename="package://ttrobot_description/meshes/Rueda3_Link.STL" />
      </geometry>
      <material
        name="">
        <color
          rgba="0.79216 0.81961 0.93333 1" />
      </material>
    </visual>
    <collision>
      <origin
        xyz="0 0 0"
        rpy="0 0 0" />
      <geometry>
        <mesh
          filename="package://ttrobot_description/meshes/Rueda3_Link.STL" />
          <!-- <cylinder length="0.135" radius="0.1"/> -->
      </geometry>
    </collision>
  </link>
  <joint
    name="Rueda3_Joint"
    type="continuous">
    <origin
      xyz="0 0.50562 -0.35997"
      rpy="0 0 0" />
    <parent
      link="base_link" />
    <child
      link="Rueda3_Link" />
    <axis
      xyz="0 1 0" />
  </joint>
  <link
    name="DirTrasIzq_Link">
    <inertial>
      <origin
        xyz="0.00015177 -0.021433 -0.080327"
        rpy="0 0 0" />
      <mass
        value="0.55669" />
      <inertia
        ixx="0.0010591"
        ixy="2.6869E-06"
        ixz="-4.9347E-07"
        iyy="0.00067989"
        iyz="6.965E-05"
        izz="0.00053192" />
    </inertial>
    <visual>
      <origin
        xyz="0 0 0"
        rpy="0 0 0" />
      <geometry>
        <mesh
          filename="package://ttrobot_description/meshes/DirTrasIzq_Link.STL" />
      </geometry>
      <material
        name="">
        <color
          rgba="0.79216 0.81961 0.93333 1" />
      </material>
    </visual>
    <collision>
      <origin
        xyz="0 0 0"
        rpy="0 0 0" />
      <geometry>
        <mesh
          filename="package://ttrobot_description/meshes/DirTrasIzq_Link.STL" />
      </geometry>
    </collision>
  </link>
  <joint
    name="DirTrasIzq_Joint"
    type="continuous">
    <origin
      xyz="-0.41975 0.50302 -0.23586"
      rpy="0 0 0" />
    <parent
      link="base_link" />
    <child
      link="DirTrasIzq_Link" />
    <axis
      xyz="0 0 1" />
  </joint>
  <link
    name="Rueda5_Link">
    <inertial>
      <origin
        xyz="-3.34E-05 0.0082498 6.6358E-08"
        rpy="0 0 0" />
      <!-- <mass
        value="0.82973" /> -->
        <mass
        value="3.6" />
      <inertia
        ixx="0.0039114"
        ixy="-1.623E-05"
        ixz="-6.0875E-12"
        iyy="0.006202"
        iyz="1.466E-12"
        izz="0.0039112" />
    </inertial>
    <visual>
      <origin
        xyz="0 0 0"
        rpy="0 0 0" />
      <geometry>
        <mesh
          filename="package://ttrobot_description/meshes/Rueda5_Link.STL" />
      </geometry>
      <material
        name="">
        <color
          rgba="0.79216 0.81961 0.93333 1" />
      </material>
    </visual>
    <collision>
      <origin
        xyz="0 0 0"
        rpy="0 0 0" />
      <geometry>
        <mesh
          filename="package://ttrobot_description/meshes/Rueda5_Link.STL" />
          <!-- <cylinder length="0.135" radius="0.1"/> -->
      </geometry>
    </collision>
  </link>
  <joint
    name="Rueda5_Joint"
    type="continuous">
    <origin
      xyz="-4.6861E-05 0.0030911 -0.12669"
      rpy="0 0 0" />
    <parent
      link="DirTrasIzq_Link" />
    <child
      link="Rueda5_Link" />
    <axis
      xyz="0 1 0" />
  </joint>
  <link
    name="DirDerFron_Link">
    <inertial>
      <origin
        xyz="0.0025837 0.021277 -0.080327"
        rpy="0 0 0" />
      <mass
        value="0.55669" />
      <inertia
        ixx="0.0010536"
        ixy="-4.5381E-05"
        ixz="-8.3958E-06"
        iyy="0.00068538"
        iyz="-6.9144E-05"
        izz="0.00053192" />
    </inertial>
    <visual>
      <origin
        xyz="0 0 0"
        rpy="0 0 0" />
      <geometry>
        <mesh
          filename="package://ttrobot_description/meshes/DirDerFron_Link.STL" />
      </geometry>
      <material
        name="">
        <color
          rgba="0.79216 0.81961 0.93333 1" />
      </material>
    </visual>
    <collision>
      <origin
        xyz="0 0 0"
        rpy="0 0 0" />
      <geometry>
        <mesh
          filename="package://ttrobot_description/meshes/DirDerFron_Link.STL" />
      </geometry>
    </collision>
  </link>
  <joint
    name="DirDerFron_Joint"
    type="continuous">
    <origin
      xyz="0.41975 -0.52405 -0.23586"
      rpy="0 0 0" />
    <parent
      link="base_link" />
    <child
      link="DirDerFron_Link" />
    <axis
      xyz="0 0 1" />
  </joint>
  <link
    name="Rueda2_Link">
    <inertial>
      <origin
        xyz="1.9188E-07 -0.011341 -8.0638E-08"
        rpy="0 0 0" />
      <!-- <mass
        value="0.82973" /> -->
        <mass
        value="3.6" />
      <inertia
        ixx="0.0039112"
        ixy="6.2237E-11"
        ixz="6.0769E-12"
        iyy="0.0062022"
        iyz="-1.5091E-12"
        izz="0.0039112" />
    </inertial>
    <visual>
      <origin
        xyz="0 0 0"
        rpy="0 0 0" />
      <geometry>
        <mesh
          filename="package://ttrobot_description/meshes/Rueda2_Link.STL" />
      </geometry>
      <material
        name="">
        <color
          rgba="0.79216 0.81961 0.93333 1" />
      </material>
    </visual>
    <collision>
      <origin
        xyz="0 0 0"
        rpy="0 0 0" />
      <geometry>
        <mesh
          filename="package://ttrobot_description/meshes/Rueda2_Link.STL" />
          <!-- <cylinder length="0.135" radius="0.1"/> -->
      </geometry>
    </collision>
  </link>
  <joint
    name="Rueda2_Joint"
    type="continuous">
    <origin
      xyz="0 0 -0.12669"
      rpy="0 0 0" />
    <parent
      link="DirDerFron_Link" />
    <child
      link="Rueda2_Link" />
    <axis
      xyz="0 -1 0" />
  </joint>
  <link
    name="Rueda4_Link">
    <inertial>
      <origin
        xyz="1.9017E-11 -0.0072065 -7.2069E-09"
        rpy="0 0 0" />
      <!-- <mass
        value="0.82974" /> -->
        <mass
        value="3.6" />
      <inertia
        ixx="0.0039112"
        ixy="6.2277E-11"
        ixz="6.0769E-12"
        iyy="0.0062022"
        iyz="-1.5091E-12"
        izz="0.0039112" />
    </inertial>
    <visual>
      <origin
        xyz="0 0 0"
        rpy="0 0 0" />
      <geometry>
        <mesh
          filename="package://ttrobot_description/meshes/Rueda4_Link.STL" />
      </geometry>
      <material
        name="">
        <color
          rgba="0.79216 0.81961 0.93333 1" />
      </material>
    </visual>
    <collision>
      <origin
        xyz="0 0 0"
        rpy="0 0 0" />
      <geometry>
        <mesh
          filename="package://ttrobot_description/meshes/Rueda4_Link.STL" />
          <!-- <cylinder length="0.135" radius="0.1"/> -->
      </geometry>
    </collision>
  </link>
  <joint
    name="Rueda4_Joint"
    type="continuous">
    <origin
      xyz="0 -0.52618 -0.35997"
      rpy="0 0 0" />
    <parent
      link="base_link" />
    <child
      link="Rueda4_Link" />
    <axis
      xyz="0 -1 0" />
  </joint>
  <link
    name="DirDerTras_Link">
    <inertial>
      <origin
        xyz="8.3093E-08 0.021434 -0.089154"
        rpy="0 0 0" />
      <mass
        value="0.55669" />
      <inertia
        ixx="0.0010591"
        ixy="7.6963E-11"
        ixz="-6.63E-12"
        iyy="0.00067987"
        iyz="-6.9652E-05"
        izz="0.00053192" />
    </inertial>
    <visual>
      <origin
        xyz="0 0 0"
        rpy="0 0 0" />
      <geometry>
        <mesh
          filename="package://ttrobot_description/meshes/DirDerTras_Link.STL" />
      </geometry>
      <material
        name="">
        <color
          rgba="0.79216 0.81961 0.93333 1" />
      </material>
    </visual>
    <collision>
      <origin
        xyz="0 0 0"
        rpy="0 0 0" />
      <geometry>
        <mesh
          filename="package://ttrobot_description/meshes/DirDerTras_Link.STL" />
      </geometry>
    </collision>
  </link>
  <joint
    name="DirDerTras_Joint"
    type="continuous">
    <origin
      xyz="-0.42145 -0.52405 -0.22737"
      rpy="0.0 0.0 0.0" />
    <parent
      link="base_link" />
    <child
      link="DirDerTras_Link" />
    <axis
      xyz="0 0 1" />
  </joint>
  <link
    name="Rueda6_Link">
    <inertial>
      <origin
        xyz="1.6411E-10 -0.0092064 -7.205E-09"
        rpy="0 0 0" />
      <!-- <mass
        value="0.82974" /> -->
        <mass
        value="3.6" />
      <inertia
        ixx="0.0039112"
        ixy="6.2295E-11"
        ixz="-2.8874E-12"
        iyy="0.0062022"
        iyz="-2.5492E-13"
        izz="0.0039112" />
    </inertial>
    <visual>
      <origin
        xyz="0 0 0"
        rpy="0 0 0" />
      <geometry>
        <mesh
          filename="package://ttrobot_description/meshes/Rueda6_Link.STL" />
      </geometry>
      <material
        name="">
        <color
          rgba="0.79216 0.81961 0.93333 1" />
      </material>
    </visual>
    <collision>
      <origin
        xyz="0 0 0"
        rpy="0 0 0" />
      <geometry>
        <mesh
          filename="package://ttrobot_description/meshes/Rueda6_Link.STL" />
          <!-- <cylinder length="0.135" radius="0.1"/> -->
      </geometry>
    </collision>
  </link>
  <joint
    name="Rueda6_Joint"
    type="continuous">
    <origin
      xyz="0 -0.0021348 -0.13552"
      rpy="0 0 0" />
    <parent
      link="DirDerTras_Link" />
    <child
      link="Rueda6_Link" />
    <axis
      xyz="0 -1 0" />
  </joint>
</robot>